Workbook

Sheet START HERE
A1: MNA Management System
A2: Madrasatul Nurul Absear • Private Basic Islamic School • Ghana
A4: Area | B4: What to do
A5: Purpose | B5: A single-workbook management system for student records, staff, attendance, fees, results, report cards, receipts and dashboards.
A6: 1. Configure | B6: Open SETTINGS first. Enter your six class names, academic year, school details and any fee/exam charges.
A7: 2. Register | B7: Enter every student once in STUDENTS. The system creates a Student ID automatically from the admission number.
A8: 3. Teachers | B8: Enter administrator/teacher records in TEACHERS and assign subjects/classes.
A9: 4. Fees | B9: Record each student's daily tuition in FEES. Saturday/Sunday = GH₵5/day; vacation Monday-Wednesday = GH₵3/day. Examination payments go in EXAM FEES.
A10: 5. Attendance | B10: Use ATTENDANCE for daily Present/Absent records. Summary is calculated automatically.
A11: 6. Results | B11: The administrator enters CA and Exam marks in RESULTS. CA is 30%; Exam is 70%. Marks above 100 are blocked.
A12: 7. Report card | B12: Choose a Student ID and academic period on REPORT CARD. The page pulls results, attendance and remarks automatically and is formatted for printing.
A13: 8. Dashboard | B13: DASHBOARD gives a management overview of enrollment, attendance, fees and academic performance.
A14: Security | B14: Sheet protection is included as a basic barrier. It is not equivalent to database security. Change the protection password before operational use.
A15: Built for Microsoft Excel on Windows. No macros are required for the core system.

Sheet SETTINGS
A1: SETTINGS
A2: Edit the green input cells. These values drive the rest of the workbook.
A4: Setting | B4: Value | C4: Notes
A5: School Name | B5: Madrasatul Nurul Absear | C5: Official school name
A6: System Name | B6: MNA Management System | C6: Workbook title
A7: Country | B7: Ghana | C7: Education system
A8: Academic Year | B8: 2026/2027 | C8: Change each academic year
A9: CA Weight | B9: 0.3 | C9: Continuous Assessment
A10: Exam Weight | B10: 0.7 | C10: Final examination
A11: Saturday Tuition | B11: 5 | C11: GH₵ per student per day
A12: Sunday Tuition | B12: 5 | C12: GH₵ per student per day
A13: Vacation Mon-Wed Tuition | B13: 3 | C13: GH₵ per student per day
A14: Currency | B14: GH₵ | C14: Display currency
A15: Protection Password | B15: MNA2026 | C15: Change this password
A17: No. | B17: Class Name | E17: Subject | F17: Applies To
A18: Class 1 | B18: Class 1 | E18: Arabic Alphabet | F18: All Classes
A19: Class 2 | B19: Class 2 | E19: Quran | F19: All Classes
A20: Class 3 | B20: Class 3 | E20: Arabic Language | F20: All Classes
A21: Class 4 | B21: Class 4 | E21: Hadith | F21: All Classes
A22: Class 5 | B22: Class 5 | E22: Seerat | F22: All Classes
A23: Class 6 | B23: Class 6 | E23: Tajweed | F23: All Classes
E24: Fiqh | F24: All Classes

Sheet STUDENTS
A1: STUDENT REGISTER
A2: Master student database • enter one row per student
A4: Student ID | B4: Admission No. | C4: Full Name | D4: Photograph / File Path | E4: Gender | F4: Date of Birth | G4: Address | H4: Contact | I4: Parent / Guardian | J4: Emergency Contact | K4: Date Admitted | L4: Class | M4: Status | N4: Current Academic Year | O4: Notes | P4: Search Key
A5: =IF(B5="","", "MNA-"&TEXT(ROW()-4,"0000")) -> MNA-0001 | B5: MNA1 | C5: Mariam Abdul Wasiu | E5: Female | F5: 40620 | H5: 555705878 | I5: PARENT | J5: 555705878 | K5: 44440 | L5: Class 5 | M5: Active | N5: 2026/2027 | P5: =IF(C5="","",LOWER(C5&"|"&B5&"|"&A5)) -> mariam abdul wasiu|mna1|mna-0001
A6: =IF(B6="","", "MNA-"&TEXT(ROW()-4,"0000")) -> MNA-0002 | B6: MNA2 | C6: Abdul Wahab Usmanu | E6: Male | F6: 39606 | H6: 272780606 | I6: PARENT | J6: 243059017 | K6: 46054 | L6: Class 5 | M6: Active | N6: 2026/2027 | P6: =IF(C6="","",LOWER(C6&"|"&B6&"|"&A6)) -> abdul wahab usmanu|mna2|mna-0002
A7: =IF(B7="","", "MNA-"&TEXT(ROW()-4,"0000")) -> MNA-0003 | B7: MNA3 | C7: Adama Jallo | E7: Female | F7: 42505 | H7: 532392207 | I7: PARENT | J7: 532392207 | K7: 44440 | L7: Class 5 | M7: Active | N7: 2026/2027 | P7: =IF(C7="","",LOWER(C7&"|"&B7&"|"&A7)) -> adama jallo|mna3|mna-0003
A8: =IF(B8="","", "MNA-"&TEXT(ROW()-4,"0000")) -> MNA-0004 | B8: MNA4 | C8: Marzooq Wakilu | E8: Male | F8: 41778 | H8: 559291706 | I8: PARENT | J8: 559291706 | K8: 44776 | L8: Class 4 | M8: Active | N8: 2026/2027 | P8: =IF(C8="","",LOWER(C8&"|"&B8&"|"&A8)) -> marzooq wakilu|mna4|mna-0004
A9: =IF(B9="","", "MNA-"&TEXT(ROW()-4,"0000")) -> MNA-0005 | B9: MNA5 | C9: Jawhar Adam Dawuni | E9: Male | F9: 41560 | H9: 534361910 | I9: PARENT | J9: 243732401 | K9: 43953 | L9: Class 4 | M9: Active | N9: 2026/2027 | P9: =IF(C9="","",LOWER(C9&"|"&B9&"|"&A9)) -> jawhar adam dawuni|mna5|mna-0005
A10: =IF(B10="","", "MNA-"&TEXT(ROW()-4,"0000")) -> MNA-0006 | B10: MNA6 | C10: Amina Yahaya | E10: Female | F10: 40858 | H10: 554994574 | I10: GUARDIAN | J10: 554994574 | K10: 44653 | L10: Class 5 | M10: Active | N10: 2026/2027 | P10: =IF(C10="","",LOWER(C10&"|"&B10&"|"&A10)) -> amina yahaya|mna6|mna-0006
A11: =IF(B11="","", "MNA-"&TEXT(ROW()-4,"0000")) -> MNA-0007 | B11: MNA7 | C11: Fatima Mohammed | E11: Female | F11: 40786 | H11: 531461611 | I11: PARENT | J11: 531461611 | K11: 45048 | L11: Class 5 | M11: Active | N11: 2026/2027 | P11: =IF(C11="","",LOWER(C11&"|"&B11&"|"&A11)) -> fatima mohammed|mna7|mna-0007
A12: =IF(B12="","", "MNA-"&TEXT(ROW()-4,"0000")) -> MNA-0008 | B12: MNA8 | C12: Fuseini Sumaila | E12: Male | F12: 41560 | H12: 243741994 | I12: PARENT | J12: 243741994 | K12: 45082 | L12: Class 4 | M12: Active | N12: 2026/2027 | P12: =IF(C12="","",LOWER(C12&"|"&B12&"|"&A12)) -> fuseini sumaila|mna8|mna-0008
A13: =IF(B13="","", "MNA-"&TEXT(ROW()-4,"0000")) -> MNA-0009 | B13: MNA9 | C13: Mohammed Mukafa | E13: Male | F13: 41179 | H13: 244117850 | I13: PARENT | J13: 244117850 | K13: 45662 | L13: Class 4 | M13: Active | N13: 2026/2027 | P13: =IF(C13="","",LOWER(C13&"|"&B13&"|"&A13)) -> mohammed mukafa|mna9|mna-0009
A14: =IF(B14="","", "MNA-"&TEXT(ROW()-4,"0000")) -> MNA-0010 | B14: MNA10 | C14: Rahanatu Kujo Rabiu | E14: Female | F14: 41540 | H14: 552880367 | I14: PARENT | J14: 552880367 | K14: 45601 | L14: Class 4 | M14: Active | N14: 2026/2027 | P14: =IF(C14="","",LOWER(C14&"|"&B14&"|"&A14)) -> rahanatu kujo rabiu|mna10|mna-0010
A15: =IF(B15="","", "MNA-"&TEXT(ROW()-4,"0000")) -> MNA-0011 | B15: MNA11 | C15: Abdul Hayyu Ibrahim | E15: Male | F15: 40638 | H15: 244389213 | I15: PARENT | J15: 533103850 | K15: 44683 | L15: Class 4 | M15: Active | N15: 2026/2027 | P15: =IF(C15="","",LOWER(C15&"|"&B15&"|"&A15)) -> abdul hayyu ibrahim|mna11|mna-0011
A16: =IF(B16="","", "MNA-"&TEXT(ROW()-4,"0000")) -> MNA-0012 | B16: MNA12 | C16: Ayishetu Abdul Fatawu | E16: Female | F16: 41031 | H16: 557969037 | I16: PARENT | J16: 249725542 | K16: 44229 | L16: Class 5 | M16: Active | N16: 2026/2027 | P16: =IF(C16="","",LOWER(C16&"|"&B16&"|"&A16)) -> ayishetu abdul fatawu|mna12|mna-0012
... A18: =IF(B18="","", "MNA-"&TEXT(ROW()-4,"0000")) -> MNA-0014 | B18: MNA14 | C18: Abdul Rahman Yakubu | E18: Male | F18: 40675 | H18: 249643958 | I18: PARENT | J18: 249643958 | K18: 45387 | L18: Class 4 | M18: Active | N18: 2026/2027 | P18: =IF(C18="","",LOWER(C18&"|"&B18&"|"&A18)) -> abdul rahman yakubu|mna14|mna-0014
A19: =IF(B19="","", "MNA-"&TEXT(ROW()-4,"0000")) -> MNA-0015 | B19: MNA15 | C19: Tofiq Mohammed | E19: Male | H19: 243741994 | I19: PARENT | J19: 243741994 | L19: Class 3 | M19: Active | N19: 2026/2027 | P19: =IF(C19="","",LOWER(C19&"|"&B19&"|"&A19)) -> tofiq mohammed |mna15|mna-0015
A20: =IF(B20="","", "MNA-"&TEXT(ROW()-4,"0000")) -> MNA-0016 | B20: MNA16 | C20: Mustafa Abubakar | E20: Male | H20: 557438424 | I20: PARENT | J20: 557438424 | L20: Class 3 | M20: Active | N20: 2026/2027 | P20: =IF(C20="","",LOWER(C20&"|"&B20&"|"&A20)) -> mustafa abubakar|mna16|mna-0016
A21: =IF(B21="","", "MNA-"&TEXT(ROW()-4,"0000")) -> MNA-0017 | B21: MNA17 | C21: Abdul Muhaimin | E21: Male | F21: 41815 | H21: 244389213 | I21: PARENT | J21: 244389213 | L21: Class 3 | M21: Active | N21: 2026/2027 | P21: =IF(C21="","",LOWER(C21&"|"&B21&"|"&A21)) -> abdul muhaimin|mna17|mna-0017
A22: =IF(B22="","", "MNA-"&TEXT(ROW()-4,"0000")) -> MNA-0018 | B22: MNA18 | C22: Rashida Mohammed | E22: Female | F22: 42342 | H22: 532398652 | I22: PARENT | J22: 532398652 | L22: Class 3 | M22: Active | N22: 2026/2027 | P22: =IF(C22="","",LOWER(C22&"|"&B22&"|"&A22)) -> rashida mohammed |mna18|mna-0018
A23: =IF(B23="","", "MNA-"&TEXT(ROW()-4,"0000")) -> MNA-0019 | B23: MNA19 | C23: Rukaya Mohammed | E23: Female | F23: 41057 | H23: 532398652 | I23: PARENT | J23: 532398652 | L23: Class 3 | M23: Active | N23: 2026/2027 | P23: =IF(C23="","",LOWER(C23&"|"&B23&"|"&A23)) -> rukaya mohammed|mna19|mna-0019
A24: =IF(B24="","", "MNA-"&TEXT(ROW()-4,"0000")) -> MNA-0020 | B24: MNA20 | C24: Farida Abdul Rashid | E24: Female | F24: 42173 | H24: 592028151 | I24: PARENT | J24: 592028151 | L24: Class 3 | M24: Active | N24: 2026/2027 | P24: =IF(C24="","",LOWER(C24&"|"&B24&"|"&A24)) -> farida abdul rashid|mna20|mna-0020
A25: =IF(B25="","", "MNA-"&TEXT(ROW()-4,"0000")) -> MNA-0021 | B25: MNA21 | C25: Hayat Abubakar | E25: Female | F25: 41973 | H25: 244160704 | I25: PARENT | J25: 244160704 | L25: Class 3 | M25: Active | N25: 2026/2027 | P25: =IF(C25="","",LOWER(C25&"|"&B25&"|"&A25)) -> hayat abubakar|mna21|mna-0021
A26: =IF(B26="","", "MNA-"&TEXT(ROW()-4,"0000")) -> MNA-0022 | B26: MNA22 | C26: Widad Ibrahim | E26: Female | F26: 42685 | H26: 531726243 | I26: PARENT | J26: 531726243 | L26: Class 3 | M26: Active | N26: 2026/2027 | P26: =IF(C26="","",LOWER(C26&"|"&B26&"|"&A26)) -> widad ibrahim|mna22|mna-0022
A27: =IF(B27="","", "MNA-"&TEXT(ROW()-4,"0000")) -> MNA-0023 | B27: MNA23 | C27: Faruk Abubakar | E27: Male | F27: 41138 | H27: 557438424 | I27: PARENT | J27: 557438424 | L27: Class 3 | M27: Active | N27: 2026/2027 | P27: =IF(C27="","",LOWER(C27&"|"&B27&"|"&A27)) -> faruk abubakar|mna23|mna-0023
A28: =IF(B28="","", "MNA-"&TEXT(ROW()-4,"0000")) -> MNA-0024 | B28: MNA24 | C28: Hidr Mustafa | E28: Male | F28: 42104 | H28: 542000155 | I28: PARENT | J28: 542000155 | L28: Class 3 | M28: Active | N28: 2026/2027 | P28: =IF(C28="","",LOWER(C28&"|"&B28&"|"&A28)) -> hidr mustafa|mna24|mna-0024
A29: =IF(B29="","", "MNA-"&TEXT(ROW()-4,"0000")) -> MNA-0025 | B29: MNA25 | C29: Hussein Humu | E29: Female | F29: 39716 | H29: 244409890 | I29: GUARDIAN | J29: 244409890 | L29: Class 4 | M29: Active | N29: 2026/2027 | P29: =IF(C29="","",LOWER(C29&"|"&B29&"|"&A29)) -> hussein humu|mna25|mna-0025
A30: =IF(B30="","", "MNA-"&TEXT(ROW()-4,"0000")) -> MNA-0026 | B30: MNA26 | C30: Mustapha Abubakar | E30: Male | F30: 41107 | H30: 593007895 | I30: GUARDIAN | J30: 593007895 | L30: Class 4 | M30: Active | N30: 2026/2027 | P30: =IF(C30="","",LOWER(C30&"|"&B30&"|"&A30)) -> mustapha abubakar|mna26|mna-0026
A31: =IF(B31="","", "MNA-"&TEXT(ROW()-4,"0000")) -> MNA-0027 | B31: MNA27 | C31: Mariam Awal | E31: Female | H31: 242489583 | I31: PARENT | J31: 242489583 | L31: Class 4 | M31: Active | N31: 2026/2027 | P31: =IF(C31="","",LOWER(C31&"|"&B31&"|"&A31)) -> mariam awal|mna27|mna-0027
A32: =IF(B32="","", "MNA-"&TEXT(ROW()-4,"0000")) -> MNA-0028 | B32: MNA28 | C32: Alhassan Abdullah | E32: Male | F32: 40877 | H32: 556983963 | I32: PARENT | J32: 556983963 | L32: Class 2 | M32: Active | N32: 2026/2027 | P32: =IF(C32="","",LOWER(C32&"|"&B32&"|"&A32)) -> alhassan abdullah|mna28|mna-0028
A33: =IF(B33="","", "MNA-"&TEXT(ROW()-4,"0000")) -> MNA-0029 | B33: MNA29 | C33: Ibrahim Mubarik | E33: Male | H33: 557488424 | I33: PARENT | J33: 557488424 | L33: Class 2 | M33: Active | N33: 2026/2027 | P33: =IF(C33="","",LOWER(C33&"|"&B33&"|"&A33)) -> ibrahim mubarik|mna29|mna-0029
A34: =IF(B34="","", "MNA-"&TEXT(ROW()-4,"0000")) -> MNA-0030 | B34: MNA30 | C34: Ibrahim Umar | E34: Male | H34: 533339370 | I34: PARENT | J34: 533339370 | L34: Class 2 | M34: Active | N34: 2026/2027 | P34: =IF(C34="","",LOWER(C34&"|"&B34&"|"&A34)) -> ibrahim umar|mna30|mna-0030
A35: =IF(B35="","", "MNA-"&TEXT(ROW()-4,"0000")) -> MNA-0031 | B35: MNA31 | C35: Abdul Majid Fatawu | E35: Male | F35: 41461 | H35: 245388413 | I35: PARENT | J35: 245388413 | L35: Class 2 | M35: Active | N35: 2026/2027 | P35: =IF(C35="","",LOWER(C35&"|"&B35&"|"&A35)) -> abdul majid fatawu|mna31|mna-0031
A36: =IF(B36="","", "MNA-"&TEXT(ROW()-4,"0000")) -> MNA-0032 | B36: MNA32 | C36: Al-had Mohammed | E36: Male | F36: 41608 | H36: 556769603 | I36: PARENT | J36: 556769603 | L36: Class 2 | M36: Active | N36: 2026/2027 | P36: =IF(C36="","",LOWER(C36&"|"&B36&"|"&A36)) -> al-had mohammed|mna32|mna-0032
A37: =IF(B37="","", "MNA-"&TEXT(ROW()-4,"0000")) -> MNA-0033 | B37: MNA33 | C37: Mohammed Fadiga | E37: Male | H37: 207301156 | I37: PARENT | J37: 207301156 | L37: Class 2 | M37: Active | N37: 2026/2027 | P37: =IF(C37="","",LOWER(C37&"|"&B37&"|"&A37)) -> mohammed fadiga|mna33|mna-0033
A38: =IF(B38="","", "MNA-"&TEXT(ROW()-4,"0000")) -> MNA-0034 | B38: MNA34 | C38: Abdul Rahman Abdul Fatawu | E38: Male | F38: 43361 | H38: 546998868 | I38: PARENT | J38: 546998868 | L38: Class 2 | M38: Active | N38: 2026/2027 | P38: =IF(C38="","",LOWER(C38&"|"&B38&"|"&A38)) -> abdul rahman abdul fatawu|mna34|mna-0034
A39: =IF(B39="","", "MNA-"&TEXT(ROW()-4,"0000")) -> MNA-0035 | B39: MNA35 | C39: Salamatu Jallo | E39: Female | F39: 42852 | H39: 532392207 | I39: PARENT | J39: 532392207 | L39: Class 2 | M39: Active | N39: 2026/2027 | P39: =IF(C39="","",LOWER(C39&"|"&B39&"|"&A39)) -> salamatu jallo|mna35|mna-0035
A40: =IF(B40="","", "MNA-"&TEXT(ROW()-4,"0000")) -> MNA-0036 | B40: MNA36 | C40: Salma Salifu | E40: Female | F40: 42517 | H40: 552020662 | I40: PARENT | J40: 552020662 | L40: Class 2 | M40: Active | N40: 2026/2027 | P40: =IF(C40="","",LOWER(C40&"|"&B40&"|"&A40)) -> salma salifu|mna36|mna-0036
A41: =IF(B41="","", "MNA-"&TEXT(ROW()-4,"0000")) -> MNA-0037 | B41: MNA37 | C41: Samira Abubakar | E41: Female | F41: 42711 | H41: 244160704 | I41: PARENT | J41: 244160704 | L41: Class 2 | M41: Active | N41: 2026/2027 | P41: =IF(C41="","",LOWER(C41&"|"&B41&"|"&A41)) -> samira abubakar|mna37|mna-0037
A42: =IF(B42="","", "MNA-"&TEXT(ROW()-4,"0000")) -> MNA-0038 | B42: MNA38 | C42: Fadila Mudasir | E42: Female | H42: 247088210 | I42: PARENT | J42: 247088210 | L42: Class 2 | M42: Active | N42: 2026/2027 | P42: =IF(C42="","",LOWER(C42&"|"&B42&"|"&A42)) -> fadila mudasir|mna38|mna-0038
...

Sheet TEACHERS
A1: TEACHERS & STAFF
A2: Teacher records and teaching assignments
A4: Teacher ID | B4: Name | C4: Class | D4: Subject | E4: Status | F4: Contact | G4: Date Joined | H4: Notes
A5: =IF(B5="","","T-"&TEXT(ROW()-4,"000"))
A6: =IF(B6="","","T-"&TEXT(ROW()-4,"000"))
A7: =IF(B7="","","T-"&TEXT(ROW()-4,"000"))
A8: =IF(B8="","","T-"&TEXT(ROW()-4,"000"))
A9: =IF(B9="","","T-"&TEXT(ROW()-4,"000"))
A10: =IF(B10="","","T-"&TEXT(ROW()-4,"000"))
A11: =IF(B11="","","T-"&TEXT(ROW()-4,"000"))
A12: =IF(B12="","","T-"&TEXT(ROW()-4,"000"))
A13: =IF(B13="","","T-"&TEXT(ROW()-4,"000"))
A14: =IF(B14="","","T-"&TEXT(ROW()-4,"000"))
A15: =IF(B15="","","T-"&TEXT(ROW()-4,"000"))
A16: =IF(B16="","","T-"&TEXT(ROW()-4,"000"))
... A24: =IF(B24="","","T-"&TEXT(ROW()-4,"000"))

Sheet FEES
A1: DAILY TUITION LEDGER
A2: Record actual attendance/tuition days. Saturday & Sunday default to GH₵5; vacation Mon-Wed default to GH₵3.
A4: Transaction ID | B4: Date | C4: Student ID | D4: Student Name | E4: Class | F4: Day | G4: School/Vacation | H4: Rate (GH₵) | I4: Amount Paid (GH₵) | J4: Balance / Note
A5: =IF(C5="","","F-"&TEXT(ROW()-4,"00000")) | D5: =IFERROR(_xludf.XLOOKUP(C5,STUDENTS!$A$5:$A$204,STUDENTS!$C$5:$C$204,""),"") | E5: =IFERROR(_xludf.XLOOKUP(C5,STUDENTS!$A$5:$A$204,STUDENTS!$L$5:$L$204,""),"") | F5: =IF(B5="","",TEXT(B5,"dddd")) | H5: =IF(B5="","",IF(OR(F5="Saturday",F5="Sunday"),SETTINGS!$B$11,IF(G5="Vacation",SETTINGS!$B$13,0))) | I5: =IF(H5="","",H5)
A6: =IF(C6="","","F-"&TEXT(ROW()-4,"00000")) | D6: =IFERROR(_xludf.XLOOKUP(C6,STUDENTS!$A$5:$A$204,STUDENTS!$C$5:$C$204,""),"") | E6: =IFERROR(_xludf.XLOOKUP(C6,STUDENTS!$A$5:$A$204,STUDENTS!$L$5:$L$204,""),"") | F6: =IF(B6="","",TEXT(B6,"dddd")) | H6: =IF(B6="","",IF(OR(F6="Saturday",F6="Sunday"),SETTINGS!$B$11,IF(G6="Vacation",SETTINGS!$B$13,0))) | I6: =IF(H6="","",H6)
A7: =IF(C7="","","F-"&TEXT(ROW()-4,"00000")) | D7: =IFERROR(_xludf.XLOOKUP(C7,STUDENTS!$A$5:$A$204,STUDENTS!$C$5:$C$204,""),"") | E7: =IFERROR(_xludf.XLOOKUP(C7,STUDENTS!$A$5:$A$204,STUDENTS!$L$5:$L$204,""),"") | F7: =IF(B7="","",TEXT(B7,"dddd")) | H7: =IF(B7="","",IF(OR(F7="Saturday",F7="Sunday"),SETTINGS!$B$11,IF(G7="Vacation",SETTINGS!$B$13,0))) | I7: =IF(H7="","",H7)
A8: =IF(C8="","","F-"&TEXT(ROW()-4,"00000")) | D8: =IFERROR(_xludf.XLOOKUP(C8,STUDENTS!$A$5:$A$204,STUDENTS!$C$5:$C$204,""),"") | E8: =IFERROR(_xludf.XLOOKUP(C8,STUDENTS!$A$5:$A$204,STUDENTS!$L$5:$L$204,""),"") | F8: =IF(B8="","",TEXT(B8,"dddd")) | H8: =IF(B8="","",IF(OR(F8="Saturday",F8="Sunday"),SETTINGS!$B$11,IF(G8="Vacation",SETTINGS!$B$13,0))) | I8: =IF(H8="","",H8)
A9: =IF(C9="","","F-"&TEXT(ROW()-4,"00000")) | D9: =IFERROR(_xludf.XLOOKUP(C9,STUDENTS!$A$5:$A$204,STUDENTS!$C$5:$C$204,""),"") | E9: =IFERROR(_xludf.XLOOKUP(C9,STUDENTS!$A$5:$A$204,STUDENTS!$L$5:$L$204,""),"") | F9: =IF(B9="","",TEXT(B9,"dddd")) | H9: =IF(B9="","",IF(OR(F9="Saturday",F9="Sunday"),SETTINGS!$B$11,IF(G9="Vacation",SETTINGS!$B$13,0))) | I9: =IF(H9="","",H9)
A10: =IF(C10="","","F-"&TEXT(ROW()-4,"00000")) | D10: =IFERROR(_xludf.XLOOKUP(C10,STUDENTS!$A$5:$A$204,STUDENTS!$C$5:$C$204,""),"") | E10: =IFERROR(_xludf.XLOOKUP(C10,STUDENTS!$A$5:$A$204,STUDENTS!$L$5:$L$204,""),"") | F10: =IF(B10="","",TEXT(B10,"dddd")) | H10: =IF(B10="","",IF(OR(F10="Saturday",F10="Sunday"),SETTINGS!$B$11,IF(G10="Vacation",SETTINGS!$B$13,0))) | I10: =IF(H10="","",H10)
A11: =IF(C11="","","F-"&TEXT(ROW()-4,"00000")) | D11: =IFERROR(_xludf.XLOOKUP(C11,STUDENTS!$A$5:$A$204,STUDENTS!$C$5:$C$204,""),"") | E11: =IFERROR(_xludf.XLOOKUP(C11,STUDENTS!$A$5:$A$204,STUDENTS!$L$5:$L$204,""),"") | F11: =IF(B11="","",TEXT(B11,"dddd")) | H11: =IF(B11="","",IF(OR(F11="Saturday",F11="Sunday"),SETTINGS!$B$11,IF(G11="Vacation",SETTINGS!$B$13,0))) | I11: =IF(H11="","",H11)
A12: =IF(C12="","","F-"&TEXT(ROW()-4,"00000")) | D12: =IFERROR(_xludf.XLOOKUP(C12,STUDENTS!$A$5:$A$204,STUDENTS!$C$5:$C$204,""),"") | E12: =IFERROR(_xludf.XLOOKUP(C12,STUDENTS!$A$5:$A$204,STUDENTS!$L$5:$L$204,""),"") | F12: =IF(B12="","",TEXT(B12,"dddd")) | H12: =IF(B12="","",IF(OR(F12="Saturday",F12="Sunday"),SETTINGS!$B$11,IF(G12="Vacation",SETTINGS!$B$13,0))) | I12: =IF(H12="","",H12)
A13: =IF(C13="","","F-"&TEXT(ROW()-4,"00000")) | D13: =IFERROR(_xludf.XLOOKUP(C13,STUDENTS!$A$5:$A$204,STUDENTS!$C$5:$C$204,""),"") | E13: =IFERROR(_xludf.XLOOKUP(C13,STUDENTS!$A$5:$A$204,STUDENTS!$L$5:$L$204,""),"") | F13: =IF(B13="","",TEXT(B13,"dddd")) | H13: =IF(B13="","",IF(OR(F13="Saturday",F13="Sunday"),SETTINGS!$B$11,IF(G13="Vacation",SETTINGS!$B$13,0))) | I13: =IF(H13="","",H13)
A14: =IF(C14="","","F-"&TEXT(ROW()-4,"00000")) | D14: =IFERROR(_xludf.XLOOKUP(C14,STUDENTS!$A$5:$A$204,STUDENTS!$C$5:$C$204,""),"") | E14: =IFERROR(_xludf.XLOOKUP(C14,STUDENTS!$A$5:$A$204,STUDENTS!$L$5:$L$204,""),"") | F14: =IF(B14="","",TEXT(B14,"dddd")) | H14: =IF(B14="","",IF(OR(F14="Saturday",F14="Sunday"),SETTINGS!$B$11,IF(G14="Vacation",SETTINGS!$B$13,0))) | I14: =IF(H14="","",H14)
A15: =IF(C15="","","F-"&TEXT(ROW()-4,"00000")) | D15: =IFERROR(_xludf.XLOOKUP(C15,STUDENTS!$A$5:$A$204,STUDENTS!$C$5:$C$204,""),"") | E15: =IFERROR(_xludf.XLOOKUP(C15,STUDENTS!$A$5:$A$204,STUDENTS!$L$5:$L$204,""),"") | F15: =IF(B15="","",TEXT(B15,"dddd")) | H15: =IF(B15="","",IF(OR(F15="Saturday",F15="Sunday"),SETTINGS!$B$11,IF(G15="Vacation",SETTINGS!$B$13,0))) | I15: =IF(H15="","",H15)
A16: =IF(C16="","","F-"&TEXT(ROW()-4,"00000")) | D16: =IFERROR(_xludf.XLOOKUP(C16,STUDENTS!$A$5:$A$204,STUDENTS!$C$5:$C$204,""),"") | E16: =IFERROR(_xludf.XLOOKUP(C16,STUDENTS!$A$5:$A$204,STUDENTS!$L$5:$L$204,""),"") | F16: =IF(B16="","",TEXT(B16,"dddd")) | H16: =IF(B16="","",IF(OR(F16="Saturday",F16="Sunday"),SETTINGS!$B$11,IF(G16="Vacation",SETTINGS!$B$13,0))) | I16: =IF(H16="","",H16)
... A1004: =IF(C1004="","","F-"&TEXT(ROW()-4,"00000")) | D1004: =IFERROR(_xludf.XLOOKUP(C1004,STUDENTS!$A$5:$A$204,STUDENTS!$C$5:$C$204,""),"") | E1004: =IFERROR(_xludf.XLOOKUP(C1004,STUDENTS!$A$5:$A$204,STUDENTS!$L$5:$L$204,""),"") | F1004: =IF(B1004="","",TEXT(B1004,"dddd")) | H1004: =IF(B1004="","",IF(OR(F1004="Saturday",F1004="Sunday"),SETTINGS!$B$11,IF(G1004="Vacation",SETTINGS!$B$13,0))) | I1004: =IF(H1004="","",H1004)

Sheet EXAM FEES
A1: EXAMINATION FEES
A2: Only examination payments are receipted here.
A4: Receipt No. | B4: Date | C4: Student ID | D4: Student Name | E4: Class | F4: Exam / Term | G4: Amount Due (GH₵) | H4: Amount Paid (GH₵) | I4: Balance (GH₵) | J4: Notes
A5: =IF(C5="","","EX-"&TEXT(ROW()-4,"00000")) | D5: =IFERROR(_xludf.XLOOKUP(C5,STUDENTS!$A$5:$A$204,STUDENTS!$C$5:$C$204,""),"") | E5: =IFERROR(_xludf.XLOOKUP(C5,STUDENTS!$A$5:$A$204,STUDENTS!$L$5:$L$204,""),"") | I5: =IF(G5="","",G5-H5)
A6: =IF(C6="","","EX-"&TEXT(ROW()-4,"00000")) | D6: =IFERROR(_xludf.XLOOKUP(C6,STUDENTS!$A$5:$A$204,STUDENTS!$C$5:$C$204,""),"") | E6: =IFERROR(_xludf.XLOOKUP(C6,STUDENTS!$A$5:$A$204,STUDENTS!$L$5:$L$204,""),"") | I6: =IF(G6="","",G6-H6)
A7: =IF(C7="","","EX-"&TEXT(ROW()-4,"00000")) | D7: =IFERROR(_xludf.XLOOKUP(C7,STUDENTS!$A$5:$A$204,STUDENTS!$C$5:$C$204,""),"") | E7: =IFERROR(_xludf.XLOOKUP(C7,STUDENTS!$A$5:$A$204,STUDENTS!$L$5:$L$204,""),"") | I7: =IF(G7="","",G7-H7)
A8: =IF(C8="","","EX-"&TEXT(ROW()-4,"00000")) | D8: =IFERROR(_xludf.XLOOKUP(C8,STUDENTS!$A$5:$A$204,STUDENTS!$C$5:$C$204,""),"") | E8: =IFERROR(_xludf.XLOOKUP(C8,STUDENTS!$A$5:$A$204,STUDENTS!$L$5:$L$204,""),"") | I8: =IF(G8="","",G8-H8)
A9: =IF(C9="","","EX-"&TEXT(ROW()-4,"00000")) | D9: =IFERROR(_xludf.XLOOKUP(C9,STUDENTS!$A$5:$A$204,STUDENTS!$C$5:$C$204,""),"") | E9: =IFERROR(_xludf.XLOOKUP(C9,STUDENTS!$A$5:$A$204,STUDENTS!$L$5:$L$204,""),"") | I9: =IF(G9="","",G9-H9)
A10: =IF(C10="","","EX-"&TEXT(ROW()-4,"00000")) | D10: =IFERROR(_xludf.XLOOKUP(C10,STUDENTS!$A$5:$A$204,STUDENTS!$C$5:$C$204,""),"") | E10: =IFERROR(_xludf.XLOOKUP(C10,STUDENTS!$A$5:$A$204,STUDENTS!$L$5:$L$204,""),"") | I10: =IF(G10="","",G10-H10)
A11: =IF(C11="","","EX-"&TEXT(ROW()-4,"00000")) | D11: =IFERROR(_xludf.XLOOKUP(C11,STUDENTS!$A$5:$A$204,STUDENTS!$C$5:$C$204,""),"") | E11: =IFERROR(_xludf.XLOOKUP(C11,STUDENTS!$A$5:$A$204,STUDENTS!$L$5:$L$204,""),"") | I11: =IF(G11="","",G11-H11)
A12: =IF(C12="","","EX-"&TEXT(ROW()-4,"00000")) | D12: =IFERROR(_xludf.XLOOKUP(C12,STUDENTS!$A$5:$A$204,STUDENTS!$C$5:$C$204,""),"") | E12: =IFERROR(_xludf.XLOOKUP(C12,STUDENTS!$A$5:$A$204,STUDENTS!$L$5:$L$204,""),"") | I12: =IF(G12="","",G12-H12)
A13: =IF(C13="","","EX-"&TEXT(ROW()-4,"00000")) | D13: =IFERROR(_xludf.XLOOKUP(C13,STUDENTS!$A$5:$A$204,STUDENTS!$C$5:$C$204,""),"") | E13: =IFERROR(_xludf.XLOOKUP(C13,STUDENTS!$A$5:$A$204,STUDENTS!$L$5:$L$204,""),"") | I13: =IF(G13="","",G13-H13)
A14: =IF(C14="","","EX-"&TEXT(ROW()-4,"00000")) | D14: =IFERROR(_xludf.XLOOKUP(C14,STUDENTS!$A$5:$A$204,STUDENTS!$C$5:$C$204,""),"") | E14: =IFERROR(_xludf.XLOOKUP(C14,STUDENTS!$A$5:$A$204,STUDENTS!$L$5:$L$204,""),"") | I14: =IF(G14="","",G14-H14)
A15: =IF(C15="","","EX-"&TEXT(ROW()-4,"00000")) | D15: =IFERROR(_xludf.XLOOKUP(C15,STUDENTS!$A$5:$A$204,STUDENTS!$C$5:$C$204,""),"") | E15: =IFERROR(_xludf.XLOOKUP(C15,STUDENTS!$A$5:$A$204,STUDENTS!$L$5:$L$204,""),"") | I15: =IF(G15="","",G15-H15)
A16: =IF(C16="","","EX-"&TEXT(ROW()-4,"00000")) | D16: =IFERROR(_xludf.XLOOKUP(C16,STUDENTS!$A$5:$A$204,STUDENTS!$C$5:$C$204,""),"") | E16: =IFERROR(_xludf.XLOOKUP(C16,STUDENTS!$A$5:$A$204,STUDENTS!$L$5:$L$204,""),"") | I16: =IF(G16="","",G16-H16)
... A404: =IF(C404="","","EX-"&TEXT(ROW()-4,"00000")) | D404: =IFERROR(_xludf.XLOOKUP(C404,STUDENTS!$A$5:$A$204,STUDENTS!$C$5:$C$204,""),"") | E404: =IFERROR(_xludf.XLOOKUP(C404,STUDENTS!$A$5:$A$204,STUDENTS!$L$5:$L$204,""),"") | I404: =IF(G404="","",G404-H404)

Sheet ATTENDANCE
A1: ATTENDANCE
A2: Daily Present/Absent register. Enter one record per student per day.
A4: Record ID | B4: Date | C4: Student ID | D4: Student Name | E4: Class | F4: Status | G4: Academic Year | H4: Present Days | I4: Absent Days | J4: Attendance %
A5: =IF(C5="","","AT-"&TEXT(ROW()-4,"00000")) | D5: =IFERROR(_xludf.XLOOKUP(C5,STUDENTS!$A$5:$A$204,STUDENTS!$C$5:$C$204,""),"") | E5: =IFERROR(_xludf.XLOOKUP(C5,STUDENTS!$A$5:$A$204,STUDENTS!$L$5:$L$204,""),"") | G5: =SETTINGS!$B$8 -> 2026/2027 | H5: =IF(F5="Present",1,0) -> 0 | I5: =IF(F5="Absent",1,0) -> 0 | J5: =IF(OR(H5="",I5=""),"",IF(H5+I5=0,"",H5/(H5+I5)))
A6: =IF(C6="","","AT-"&TEXT(ROW()-4,"00000")) | D6: =IFERROR(_xludf.XLOOKUP(C6,STUDENTS!$A$5:$A$204,STUDENTS!$C$5:$C$204,""),"") | E6: =IFERROR(_xludf.XLOOKUP(C6,STUDENTS!$A$5:$A$204,STUDENTS!$L$5:$L$204,""),"") | G6: =SETTINGS!$B$8 -> 2026/2027 | H6: =IF(F6="Present",1,0) -> 0 | I6: =IF(F6="Absent",1,0) -> 0 | J6: =IF(OR(H6="",I6=""),"",IF(H6+I6=0,"",H6/(H6+I6)))
A7: =IF(C7="","","AT-"&TEXT(ROW()-4,"00000")) | D7: =IFERROR(_xludf.XLOOKUP(C7,STUDENTS!$A$5:$A$204,STUDENTS!$C$5:$C$204,""),"") | E7: =IFERROR(_xludf.XLOOKUP(C7,STUDENTS!$A$5:$A$204,STUDENTS!$L$5:$L$204,""),"") | G7: =SETTINGS!$B$8 -> 2026/2027 | H7: =IF(F7="Present",1,0) -> 0 | I7: =IF(F7="Absent",1,0) -> 0 | J7: =IF(OR(H7="",I7=""),"",IF(H7+I7=0,"",H7/(H7+I7)))
A8: =IF(C8="","","AT-"&TEXT(ROW()-4,"00000")) | D8: =IFERROR(_xludf.XLOOKUP(C8,STUDENTS!$A$5:$A$204,STUDENTS!$C$5:$C$204,""),"") | E8: =IFERROR(_xludf.XLOOKUP(C8,STUDENTS!$A$5:$A$204,STUDENTS!$L$5:$L$204,""),"") | G8: =SETTINGS!$B$8 -> 2026/2027 | H8: =IF(F8="Present",1,0) -> 0 | I8: =IF(F8="Absent",1,0) -> 0 | J8: =IF(OR(H8="",I8=""),"",IF(H8+I8=0,"",H8/(H8+I8)))
A9: =IF(C9="","","AT-"&TEXT(ROW()-4,"00000")) | D9: =IFERROR(_xludf.XLOOKUP(C9,STUDENTS!$A$5:$A$204,STUDENTS!$C$5:$C$204,""),"") | E9: =IFERROR(_xludf.XLOOKUP(C9,STUDENTS!$A$5:$A$204,STUDENTS!$L$5:$L$204,""),"") | G9: =SETTINGS!$B$8 -> 2026/2027 | H9: =IF(F9="Present",1,0) -> 0 | I9: =IF(F9="Absent",1,0) -> 0 | J9: =IF(OR(H9="",I9=""),"",IF(H9+I9=0,"",H9/(H9+I9)))
A10: =IF(C10="","","AT-"&TEXT(ROW()-4,"00000")) | D10: =IFERROR(_xludf.XLOOKUP(C10,STUDENTS!$A$5:$A$204,STUDENTS!$C$5:$C$204,""),"") | E10: =IFERROR(_xludf.XLOOKUP(C10,STUDENTS!$A$5:$A$204,STUDENTS!$L$5:$L$204,""),"") | G10: =SETTINGS!$B$8 -> 2026/2027 | H10: =IF(F10="Present",1,0) -> 0 | I10: =IF(F10="Absent",1,0) -> 0 | J10: =IF(OR(H10="",I10=""),"",IF(H10+I10=0,"",H10/(H10+I10)))
A11: =IF(C11="","","AT-"&TEXT(ROW()-4,"00000")) | D11: =IFERROR(_xludf.XLOOKUP(C11,STUDENTS!$A$5:$A$204,STUDENTS!$C$5:$C$204,""),"") | E11: =IFERROR(_xludf.XLOOKUP(C11,STUDENTS!$A$5:$A$204,STUDENTS!$L$5:$L$204,""),"") | G11: =SETTINGS!$B$8 -> 2026/2027 | H11: =IF(F11="Present",1,0) -> 0 | I11: =IF(F11="Absent",1,0) -> 0 | J11: =IF(OR(H11="",I11=""),"",IF(H11+I11=0,"",H11/(H11+I11)))
A12: =IF(C12="","","AT-"&TEXT(ROW()-4,"00000")) | D12: =IFERROR(_xludf.XLOOKUP(C12,STUDENTS!$A$5:$A$204,STUDENTS!$C$5:$C$204,""),"") | E12: =IFERROR(_xludf.XLOOKUP(C12,STUDENTS!$A$5:$A$204,STUDENTS!$L$5:$L$204,""),"") | G12: =SETTINGS!$B$8 -> 2026/2027 | H12: =IF(F12="Present",1,0) -> 0 | I12: =IF(F12="Absent",1,0) -> 0 | J12: =IF(OR(H12="",I12=""),"",IF(H12+I12=0,"",H12/(H12+I12)))
A13: =IF(C13="","","AT-"&TEXT(ROW()-4,"00000")) | D13: =IFERROR(_xludf.XLOOKUP(C13,STUDENTS!$A$5:$A$204,STUDENTS!$C$5:$C$204,""),"") | E13: =IFERROR(_xludf.XLOOKUP(C13,STUDENTS!$A$5:$A$204,STUDENTS!$L$5:$L$204,""),"") | G13: =SETTINGS!$B$8 -> 2026/2027 | H13: =IF(F13="Present",1,0) -> 0 | I13: =IF(F13="Absent",1,0) -> 0 | J13: =IF(OR(H13="",I13=""),"",IF(H13+I13=0,"",H13/(H13+I13)))
A14: =IF(C14="","","AT-"&TEXT(ROW()-4,"00000")) | D14: =IFERROR(_xludf.XLOOKUP(C14,STUDENTS!$A$5:$A$204,STUDENTS!$C$5:$C$204,""),"") | E14: =IFERROR(_xludf.XLOOKUP(C14,STUDENTS!$A$5:$A$204,STUDENTS!$L$5:$L$204,""),"") | G14: =SETTINGS!$B$8 -> 2026/2027 | H14: =IF(F14="Present",1,0) -> 0 | I14: =IF(F14="Absent",1,0) -> 0 | J14: =IF(OR(H14="",I14=""),"",IF(H14+I14=0,"",H14/(H14+I14)))
A15: =IF(C15="","","AT-"&TEXT(ROW()-4,"00000")) | D15: =IFERROR(_xludf.XLOOKUP(C15,STUDENTS!$A$5:$A$204,STUDENTS!$C$5:$C$204,""),"") | E15: =IFERROR(_xludf.XLOOKUP(C15,STUDENTS!$A$5:$A$204,STUDENTS!$L$5:$L$204,""),"") | G15: =SETTINGS!$B$8 -> 2026/2027 | H15: =IF(F15="Present",1,0) -> 0 | I15: =IF(F15="Absent",1,0) -> 0 | J15: =IF(OR(H15="",I15=""),"",IF(H15+I15=0,"",H15/(H15+I15)))
A16: =IF(C16="","","AT-"&TEXT(ROW()-4,"00000")) | D16: =IFERROR(_xludf.XLOOKUP(C16,STUDENTS!$A$5:$A$204,STUDENTS!$C$5:$C$204,""),"") | E16: =IFERROR(_xludf.XLOOKUP(C16,STUDENTS!$A$5:$A$204,STUDENTS!$L$5:$L$204,""),"") | G16: =SETTINGS!$B$8 -> 2026/2027 | H16: =IF(F16="Present",1,0) -> 0 | I16: =IF(F16="Absent",1,0) -> 0 | J16: =IF(OR(H16="",I16=""),"",IF(H16+I16=0,"",H16/(H16+I16)))
... A1204: =IF(C1204="","","AT-"&TEXT(ROW()-4,"00000")) | D1204: =IFERROR(_xludf.XLOOKUP(C1204,STUDENTS!$A$5:$A$204,STUDENTS!$C$5:$C$204,""),"") | E1204: =IFERROR(_xludf.XLOOKUP(C1204,STUDENTS!$A$5:$A$204,STUDENTS!$L$5:$L$204,""),"") | G1204: =SETTINGS!$B$8 -> 2026/2027 | H1204: =IF(F1204="Present",1,0) -> 0 | I1204: =IF(F1204="Absent",1,0) -> 0 | J1204: =IF(OR(H1204="",I1204=""),"",IF(H1204+I1204=0,"",H1204/(H1204+I1204)))

Sheet RESULTS
A1: RESULTS ENTRY
A2: Administrator-only result entry • CA 30% + Exam 70% • marks must be 0–100
A4: Result ID | B4: Academic Year | C4: Term | D4: Student ID | E4: Student Name | F4: Class | G4: Subject | H4: CA Mark | I4: Exam Mark | J4: Weighted CA | K4: Weighted Exam | L4: Total | M4: Grade | N4: Position | O4: Teacher Remark
A5: =IF(D5="","","R-"&TEXT(ROW()-4,"00000")) | E5: =IFERROR(_xludf.XLOOKUP(D5,STUDENTS!$A$5:$A$204,STUDENTS!$C$5:$C$204,""),"") | F5: =IFERROR(_xludf.XLOOKUP(D5,STUDENTS!$A$5:$A$204,STUDENTS!$L$5:$L$204,""),"") | J5: =IF(H5="","",H5*SETTINGS!$B$9) | K5: =IF(I5="","",I5*SETTINGS!$B$10) | L5: =IF(OR(H5="",I5=""),"",J5+K5) | M5: =IF(L5="","",IF(L5>=80,"A",IF(L5>=70,"B",IF(L5>=60,"C",IF(L5>=50,"D","F"))))) | N5: =IF(L5="","",1+COUNTIFS($F$5:$F$1004,F5,$C$5:$C$1004,C5,$G$5:$G$1004,G5,$L$5:$L$1004,">"&L5))
A6: =IF(D6="","","R-"&TEXT(ROW()-4,"00000")) | E6: =IFERROR(_xludf.XLOOKUP(D6,STUDENTS!$A$5:$A$204,STUDENTS!$C$5:$C$204,""),"") | F6: =IFERROR(_xludf.XLOOKUP(D6,STUDENTS!$A$5:$A$204,STUDENTS!$L$5:$L$204,""),"") | J6: =IF(H6="","",H6*SETTINGS!$B$9) | K6: =IF(I6="","",I6*SETTINGS!$B$10) | L6: =IF(OR(H6="",I6=""),"",J6+K6) | M6: =IF(L6="","",IF(L6>=80,"A",IF(L6>=70,"B",IF(L6>=60,"C",IF(L6>=50,"D","F"))))) | N6: =IF(L6="","",1+COUNTIFS($F$5:$F$1004,F6,$C$5:$C$1004,C6,$G$5:$G$1004,G6,$L$5:$L$1004,">"&L6))
A7: =IF(D7="","","R-"&TEXT(ROW()-4,"00000")) | E7: =IFERROR(_xludf.XLOOKUP(D7,STUDENTS!$A$5:$A$204,STUDENTS!$C$5:$C$204,""),"") | F7: =IFERROR(_xludf.XLOOKUP(D7,STUDENTS!$A$5:$A$204,STUDENTS!$L$5:$L$204,""),"") | J7: =IF(H7="","",H7*SETTINGS!$B$9) | K7: =IF(I7="","",I7*SETTINGS!$B$10) | L7: =IF(OR(H7="",I7=""),"",J7+K7) | M7: =IF(L7="","",IF(L7>=80,"A",IF(L7>=70,"B",IF(L7>=60,"C",IF(L7>=50,"D","F"))))) | N7: =IF(L7="","",1+COUNTIFS($F$5:$F$1004,F7,$C$5:$C$1004,C7,$G$5:$G$1004,G7,$L$5:$L$1004,">"&L7))
A8: =IF(D8="","","R-"&TEXT(ROW()-4,"00000")) | E8: =IFERROR(_xludf.XLOOKUP(D8,STUDENTS!$A$5:$A$204,STUDENTS!$C$5:$C$204,""),"") | F8: =IFERROR(_xludf.XLOOKUP(D8,STUDENTS!$A$5:$A$204,STUDENTS!$L$5:$L$204,""),"") | J8: =IF(H8="","",H8*SETTINGS!$B$9) | K8: =IF(I8="","",I8*SETTINGS!$B$10) | L8: =IF(OR(H8="",I8=""),"",J8+K8) | M8: =IF(L8="","",IF(L8>=80,"A",IF(L8>=70,"B",IF(L8>=60,"C",IF(L8>=50,"D","F"))))) | N8: =IF(L8="","",1+COUNTIFS($F$5:$F$1004,F8,$C$5:$C$1004,C8,$G$5:$G$1004,G8,$L$5:$L$1004,">"&L8))
A9: =IF(D9="","","R-"&TEXT(ROW()-4,"00000")) | E9: =IFERROR(_xludf.XLOOKUP(D9,STUDENTS!$A$5:$A$204,STUDENTS!$C$5:$C$204,""),"") | F9: =IFERROR(_xludf.XLOOKUP(D9,STUDENTS!$A$5:$A$204,STUDENTS!$L$5:$L$204,""),"") | J9: =IF(H9="","",H9*SETTINGS!$B$9) | K9: =IF(I9="","",I9*SETTINGS!$B$10) | L9: =IF(OR(H9="",I9=""),"",J9+K9) | M9: =IF(L9="","",IF(L9>=80,"A",IF(L9>=70,"B",IF(L9>=60,"C",IF(L9>=50,"D","F"))))) | N9: =IF(L9="","",1+COUNTIFS($F$5:$F$1004,F9,$C$5:$C$1004,C9,$G$5:$G$1004,G9,$L$5:$L$1004,">"&L9))
A10: =IF(D10="","","R-"&TEXT(ROW()-4,"00000")) | E10: =IFERROR(_xludf.XLOOKUP(D10,STUDENTS!$A$5:$A$204,STUDENTS!$C$5:$C$204,""),"") | F10: =IFERROR(_xludf.XLOOKUP(D10,STUDENTS!$A$5:$A$204,STUDENTS!$L$5:$L$204,""),"") | J10: =IF(H10="","",H10*SETTINGS!$B$9) | K10: =IF(I10="","",I10*SETTINGS!$B$10) | L10: =IF(OR(H10="",I10=""),"",J10+K10) | M10: =IF(L10="","",IF(L10>=80,"A",IF(L10>=70,"B",IF(L10>=60,"C",IF(L10>=50,"D","F"))))) | N10: =IF(L10="","",1+COUNTIFS($F$5:$F$1004,F10,$C$5:$C$1004,C10,$G$5:$G$1004,G10,$L$5:$L$1004,">"&L10))
A11: =IF(D11="","","R-"&TEXT(ROW()-4,"00000")) | E11: =IFERROR(_xludf.XLOOKUP(D11,STUDENTS!$A$5:$A$204,STUDENTS!$C$5:$C$204,""),"") | F11: =IFERROR(_xludf.XLOOKUP(D11,STUDENTS!$A$5:$A$204,STUDENTS!$L$5:$L$204,""),"") | J11: =IF(H11="","",H11*SETTINGS!$B$9) | K11: =IF(I11="","",I11*SETTINGS!$B$10) | L11: =IF(OR(H11="",I11=""),"",J11+K11) | M11: =IF(L11="","",IF(L11>=80,"A",IF(L11>=70,"B",IF(L11>=60,"C",IF(L11>=50,"D","F"))))) | N11: =IF(L11="","",1+COUNTIFS($F$5:$F$1004,F11,$C$5:$C$1004,C11,$G$5:$G$1004,G11,$L$5:$L$1004,">"&L11))
A12: =IF(D12="","","R-"&TEXT(ROW()-4,"00000")) | E12: =IFERROR(_xludf.XLOOKUP(D12,STUDENTS!$A$5:$A$204,STUDENTS!$C$5:$C$204,""),"") | F12: =IFERROR(_xludf.XLOOKUP(D12,STUDENTS!$A$5:$A$204,STUDENTS!$L$5:$L$204,""),"") | J12: =IF(H12="","",H12*SETTINGS!$B$9) | K12: =IF(I12="","",I12*SETTINGS!$B$10) | L12: =IF(OR(H12="",I12=""),"",J12+K12) | M12: =IF(L12="","",IF(L12>=80,"A",IF(L12>=70,"B",IF(L12>=60,"C",IF(L12>=50,"D","F"))))) | N12: =IF(L12="","",1+COUNTIFS($F$5:$F$1004,F12,$C$5:$C$1004,C12,$G$5:$G$1004,G12,$L$5:$L$1004,">"&L12))
A13: =IF(D13="","","R-"&TEXT(ROW()-4,"00000")) | E13: =IFERROR(_xludf.XLOOKUP(D13,STUDENTS!$A$5:$A$204,STUDENTS!$C$5:$C$204,""),"") | F13: =IFERROR(_xludf.XLOOKUP(D13,STUDENTS!$A$5:$A$204,STUDENTS!$L$5:$L$204,""),"") | J13: =IF(H13="","",H13*SETTINGS!$B$9) | K13: =IF(I13="","",I13*SETTINGS!$B$10) | L13: =IF(OR(H13="",I13=""),"",J13+K13) | M13: =IF(L13="","",IF(L13>=80,"A",IF(L13>=70,"B",IF(L13>=60,"C",IF(L13>=50,"D","F"))))) | N13: =IF(L13="","",1+COUNTIFS($F$5:$F$1004,F13,$C$5:$C$1004,C13,$G$5:$G$1004,G13,$L$5:$L$1004,">"&L13))
A14: =IF(D14="","","R-"&TEXT(ROW()-4,"00000")) | E14: =IFERROR(_xludf.XLOOKUP(D14,STUDENTS!$A$5:$A$204,STUDENTS!$C$5:$C$204,""),"") | F14: =IFERROR(_xludf.XLOOKUP(D14,STUDENTS!$A$5:$A$204,STUDENTS!$L$5:$L$204,""),"") | J14: =IF(H14="","",H14*SETTINGS!$B$9) | K14: =IF(I14="","",I14*SETTINGS!$B$10) | L14: =IF(OR(H14="",I14=""),"",J14+K14) | M14: =IF(L14="","",IF(L14>=80,"A",IF(L14>=70,"B",IF(L14>=60,"C",IF(L14>=50,"D","F"))))) | N14: =IF(L14="","",1+COUNTIFS($F$5:$F$1004,F14,$C$5:$C$1004,C14,$G$5:$G$1004,G14,$L$5:$L$1004,">"&L14))
A15: =IF(D15="","","R-"&TEXT(ROW()-4,"00000")) | E15: =IFERROR(_xludf.XLOOKUP(D15,STUDENTS!$A$5:$A$204,STUDENTS!$C$5:$C$204,""),"") | F15: =IFERROR(_xludf.XLOOKUP(D15,STUDENTS!$A$5:$A$204,STUDENTS!$L$5:$L$204,""),"") | J15: =IF(H15="","",H15*SETTINGS!$B$9) | K15: =IF(I15="","",I15*SETTINGS!$B$10) | L15: =IF(OR(H15="",I15=""),"",J15+K15) | M15: =IF(L15="","",IF(L15>=80,"A",IF(L15>=70,"B",IF(L15>=60,"C",IF(L15>=50,"D","F"))))) | N15: =IF(L15="","",1+COUNTIFS($F$5:$F$1004,F15,$C$5:$C$1004,C15,$G$5:$G$1004,G15,$L$5:$L$1004,">"&L15))
A16: =IF(D16="","","R-"&TEXT(ROW()-4,"00000")) | E16: =IFERROR(_xludf.XLOOKUP(D16,STUDENTS!$A$5:$A$204,STUDENTS!$C$5:$C$204,""),"") | F16: =IFERROR(_xludf.XLOOKUP(D16,STUDENTS!$A$5:$A$204,STUDENTS!$L$5:$L$204,""),"") | J16: =IF(H16="","",H16*SETTINGS!$B$9) | K16: =IF(I16="","",I16*SETTINGS!$B$10) | L16: =IF(OR(H16="",I16=""),"",J16+K16) | M16: =IF(L16="","",IF(L16>=80,"A",IF(L16>=70,"B",IF(L16>=60,"C",IF(L16>=50,"D","F"))))) | N16: =IF(L16="","",1+COUNTIFS($F$5:$F$1004,F16,$C$5:$C$1004,C16,$G$5:$G$1004,G16,$L$5:$L$1004,">"&L16))
... A1004: =IF(D1004="","","R-"&TEXT(ROW()-4,"00000")) | E1004: =IFERROR(_xludf.XLOOKUP(D1004,STUDENTS!$A$5:$A$204,STUDENTS!$C$5:$C$204,""),"") | F1004: =IFERROR(_xludf.XLOOKUP(D1004,STUDENTS!$A$5:$A$204,STUDENTS!$L$5:$L$204,""),"") | J1004: =IF(H1004="","",H1004*SETTINGS!$B$9) | K1004: =IF(I1004="","",I1004*SETTINGS!$B$10) | L1004: =IF(OR(H1004="",I1004=""),"",J1004+K1004) | M1004: =IF(L1004="","",IF(L1004>=80,"A",IF(L1004>=70,"B",IF(L1004>=60,"C",IF(L1004>=50,"D","F"))))) | N1004: =IF(L1004="","",1+COUNTIFS($F$5:$F$1004,F1004,$C$5:$C$1004,C1004,$G$5:$G$1004,G1004,$L$5:$L$1004,">"&L1004))

Sheet REPORT CARD
A1: MNA REPORT CARD
A2: Select a Student ID and term below. The report pulls results and attendance automatically.
A4: Student ID | D4: Term | G4: Academic Year | H4: =SETTINGS!B8 -> 2026/2027
A6: Student Name | D6: Class | G6: Gender
A8: Attendance
B9: Present Days | C9: Absent Days | D9: Attendance %
B10: =COUNTIFS(ATTENDANCE!$C$5:$C$1204,$B$4,ATTENDANCE!$F$5:$F$1204,"Present") -> 0 | C10: =COUNTIFS(ATTENDANCE!$C$5:$C$1204,$B$4,ATTENDANCE!$F$5:$F$1204,"Absent") -> 0 | D10: =IF(B10+C10=0,"",B10/(B10+C10))
A12: Subject | B12: CA (30%) | C12: Exam (70%) | D12: Total | E12: Grade | F12: Position | G12: Teacher Remark
A13: =IFERROR(INDEX(SETTINGS!$E$18:$E$24,1),"") -> Arabic Alphabet | B13: =IFERROR(SUMIFS(RESULTS!$H$5:$H$1004,RESULTS!$D$5:$D$1004,$B$4,RESULTS!$C$5:$C$1004,$E$4,RESULTS!$G$5:$G$1004,$A13),"") -> 0 | C13: =IFERROR(SUMIFS(RESULTS!$I$5:$I$1004,RESULTS!$D$5:$D$1004,$B$4,RESULTS!$C$5:$C$1004,$E$4,RESULTS!$G$5:$G$1004,$A13),"") -> 0 | D13: =IF(OR(B13="",C13=""),"",B13*SETTINGS!$B$9+C13*SETTINGS!$B$10) -> 0 | E13: =IF(D13="","",IF(D13>=80,"A",IF(D13>=70,"B",IF(D13>=60,"C",IF(D13>=50,"D","F"))))) -> F | F13: =IF(D13="","",1+COUNTIFS(RESULTS!$F$5:$F$1004,$E$6,RESULTS!$C$5:$C$1004,$E$4,RESULTS!$G$5:$G$1004,$A13,RESULTS!$L$5:$L$1004,">"&D13)) -> 1 | G13: =IFERROR(INDEX(RESULTS!$O$5:$O$1004,MATCH(1,(RESULTS!$D$5:$D$1004=$B$4)*(RESULTS!$C$5:$C$1004=$E$4)*(RESULTS!$G$5:$G$1004=$A13),0)),"")
A14: =IFERROR(INDEX(SETTINGS!$E$18:$E$24,2),"") -> Quran | B14: =IFERROR(SUMIFS(RESULTS!$H$5:$H$1004,RESULTS!$D$5:$D$1004,$B$4,RESULTS!$C$5:$C$1004,$E$4,RESULTS!$G$5:$G$1004,$A14),"") -> 0 | C14: =IFERROR(SUMIFS(RESULTS!$I$5:$I$1004,RESULTS!$D$5:$D$1004,$B$4,RESULTS!$C$5:$C$1004,$E$4,RESULTS!$G$5:$G$1004,$A14),"") -> 0 | D14: =IF(OR(B14="",C14=""),"",B14*SETTINGS!$B$9+C14*SETTINGS!$B$10) -> 0 | E14: =IF(D14="","",IF(D14>=80,"A",IF(D14>=70,"B",IF(D14>=60,"C",IF(D14>=50,"D","F"))))) -> F | F14: =IF(D14="","",1+COUNTIFS(RESULTS!$F$5:$F$1004,$E$6,RESULTS!$C$5:$C$1004,$E$4,RESULTS!$G$5:$G$1004,$A14,RESULTS!$L$5:$L$1004,">"&D14)) -> 1 | G14: =IFERROR(INDEX(RESULTS!$O$5:$O$1004,MATCH(1,(RESULTS!$D$5:$D$1004=$B$4)*(RESULTS!$C$5:$C$1004=$E$4)*(RESULTS!$G$5:$G$1004=$A14),0)),"")
A15: =IFERROR(INDEX(SETTINGS!$E$18:$E$24,3),"") -> Arabic Language | B15: =IFERROR(SUMIFS(RESULTS!$H$5:$H$1004,RESULTS!$D$5:$D$1004,$B$4,RESULTS!$C$5:$C$1004,$E$4,RESULTS!$G$5:$G$1004,$A15),"") -> 0 | C15: =IFERROR(SUMIFS(RESULTS!$I$5:$I$1004,RESULTS!$D$5:$D$1004,$B$4,RESULTS!$C$5:$C$1004,$E$4,RESULTS!$G$5:$G$1004,$A15),"") -> 0 | D15: =IF(OR(B15="",C15=""),"",B15*SETTINGS!$B$9+C15*SETTINGS!$B$10) -> 0 | E15: =IF(D15="","",IF(D15>=80,"A",IF(D15>=70,"B",IF(D15>=60,"C",IF(D15>=50,"D","F"))))) -> F | F15: =IF(D15="","",1+COUNTIFS(RESULTS!$F$5:$F$1004,$E$6,RESULTS!$C$5:$C$1004,$E$4,RESULTS!$G$5:$G$1004,$A15,RESULTS!$L$5:$L$1004,">"&D15)) -> 1 | G15: =IFERROR(INDEX(RESULTS!$O$5:$O$1004,MATCH(1,(RESULTS!$D$5:$D$1004=$B$4)*(RESULTS!$C$5:$C$1004=$E$4)*(RESULTS!$G$5:$G$1004=$A15),0)),"")
A16: =IFERROR(INDEX(SETTINGS!$E$18:$E$24,4),"") -> Hadith | B16: =IFERROR(SUMIFS(RESULTS!$H$5:$H$1004,RESULTS!$D$5:$D$1004,$B$4,RESULTS!$C$5:$C$1004,$E$4,RESULTS!$G$5:$G$1004,$A16),"") -> 0 | C16: =IFERROR(SUMIFS(RESULTS!$I$5:$I$1004,RESULTS!$D$5:$D$1004,$B$4,RESULTS!$C$5:$C$1004,$E$4,RESULTS!$G$5:$G$1004,$A16),"") -> 0 | D16: =IF(OR(B16="",C16=""),"",B16*SETTINGS!$B$9+C16*SETTINGS!$B$10) -> 0 | E16: =IF(D16="","",IF(D16>=80,"A",IF(D16>=70,"B",IF(D16>=60,"C",IF(D16>=50,"D","F"))))) -> F | F16: =IF(D16="","",1+COUNTIFS(RESULTS!$F$5:$F$1004,$E$6,RESULTS!$C$5:$C$1004,$E$4,RESULTS!$G$5:$G$1004,$A16,RESULTS!$L$5:$L$1004,">"&D16)) -> 1 | G16: =IFERROR(INDEX(RESULTS!$O$5:$O$1004,MATCH(1,(RESULTS!$D$5:$D$1004=$B$4)*(RESULTS!$C$5:$C$1004=$E$4)*(RESULTS!$G$5:$G$1004=$A16),0)),"")
A17: =IFERROR(INDEX(SETTINGS!$E$18:$E$24,5),"") -> Seerat | B17: =IFERROR(SUMIFS(RESULTS!$H$5:$H$1004,RESULTS!$D$5:$D$1004,$B$4,RESULTS!$C$5:$C$1004,$E$4,RESULTS!$G$5:$G$1004,$A17),"") -> 0 | C17: =IFERROR(SUMIFS(RESULTS!$I$5:$I$1004,RESULTS!$D$5:$D$1004,$B$4,RESULTS!$C$5:$C$1004,$E$4,RESULTS!$G$5:$G$1004,$A17),"") -> 0 | D17: =IF(OR(B17="",C17=""),"",B17*SETTINGS!$B$9+C17*SETTINGS!$B$10) -> 0 | E17: =IF(D17="","",IF(D17>=80,"A",IF(D17>=70,"B",IF(D17>=60,"C",IF(D17>=50,"D","F"))))) -> F | F17: =IF(D17="","",1+COUNTIFS(RESULTS!$F$5:$F$1004,$E$6,RESULTS!$C$5:$C$1004,$E$4,RESULTS!$G$5:$G$1004,$A17,RESULTS!$L$5:$L$1004,">"&D17)) -> 1 | G17: =IFERROR(INDEX(RESULTS!$O$5:$O$1004,MATCH(1,(RESULTS!$D$5:$D$1004=$B$4)*(RESULTS!$C$5:$C$1004=$E$4)*(RESULTS!$G$5:$G$1004=$A17),0)),"")
A18: =IFERROR(INDEX(SETTINGS!$E$18:$E$24,6),"") -> Tajweed | B18: =IFERROR(SUMIFS(RESULTS!$H$5:$H$1004,RESULTS!$D$5:$D$1004,$B$4,RESULTS!$C$5:$C$1004,$E$4,RESULTS!$G$5:$G$1004,$A18),"") -> 0 | C18: =IFERROR(SUMIFS(RESULTS!$I$5:$I$1004,RESULTS!$D$5:$D$1004,$B$4,RESULTS!$C$5:$C$1004,$E$4,RESULTS!$G$5:$G$1004,$A18),"") -> 0 | D18: =IF(OR(B18="",C18=""),"",B18*SETTINGS!$B$9+C18*SETTINGS!$B$10) -> 0 | E18: =IF(D18="","",IF(D18>=80,"A",IF(D18>=70,"B",IF(D18>=60,"C",IF(D18>=50,"D","F"))))) -> F | F18: =IF(D18="","",1+COUNTIFS(RESULTS!$F$5:$F$1004,$E$6,RESULTS!$C$5:$C$1004,$E$4,RESULTS!$G$5:$G$1004,$A18,RESULTS!$L$5:$L$1004,">"&D18)) -> 1 | G18: =IFERROR(INDEX(RESULTS!$O$5:$O$1004,MATCH(1,(RESULTS!$D$5:$D$1004=$B$4)*(RESULTS!$C$5:$C$1004=$E$4)*(RESULTS!$G$5:$G$1004=$A18),0)),"")
A19: =IFERROR(INDEX(SETTINGS!$E$18:$E$24,7),"") -> Fiqh | B19: =IFERROR(SUMIFS(RESULTS!$H$5:$H$1004,RESULTS!$D$5:$D$1004,$B$4,RESULTS!$C$5:$C$1004,$E$4,RESULTS!$G$5:$G$1004,$A19),"") -> 0 | C19: =IFERROR(SUMIFS(RESULTS!$I$5:$I$1004,RESULTS!$D$5:$D$1004,$B$4,RESULTS!$C$5:$C$1004,$E$4,RESULTS!$G$5:$G$1004,$A19),"") -> 0 | D19: =IF(OR(B19="",C19=""),"",B19*SETTINGS!$B$9+C19*SETTINGS!$B$10) -> 0 | E19: =IF(D19="","",IF(D19>=80,"A",IF(D19>=70,"B",IF(D19>=60,"C",IF(D19>=50,"D","F"))))) -> F | F19: =IF(D19="","",1+COUNTIFS(RESULTS!$F$5:$F$1004,$E$6,RESULTS!$C$5:$C$1004,$E$4,RESULTS!$G$5:$G$1004,$A19,RESULTS!$L$5:$L$1004,">"&D19)) -> 1 | G19: =IFERROR(INDEX(RESULTS!$O$5:$O$1004,MATCH(1,(RESULTS!$D$5:$D$1004=$B$4)*(RESULTS!$C$5:$C$1004=$E$4)*(RESULTS!$G$5:$G$1004=$A19),0)),"")
A22: Overall Average | B22: =IFERROR(AVERAGE(D13:D19),"") -> 0 | D22: Overall Grade | E22: =IF(B22="","",IF(B22>=80,"A",IF(B22>=70,"B",IF(B22>=60,"C",IF(B22>=50,"D","F"))))) -> F | G22: Attendance | H22: =D10
A24: Teacher's General Remark | B24: =IF($B$4="","",IF(B22>=80,"Excellent performance. Keep it up.",IF(B22>=70,"Very good performance. Continue working hard.",IF(B22>=60,"Good performance. More effort can produce better results.",IF(B22>=50,"Satisfactory performance. Improvement is needed.","Performance requires significant improvement.")))))
A27: Administrator's Signature: ______________________________ | F27: Date: __________________

Sheet EXAM RECEIPT
A1: EXAMINATION FEE RECEIPT
A2: Printable receipt • enter/select a Receipt No.
A4: Receipt No.
A6: Student ID | B6: =IFERROR(_xludf.XLOOKUP($B$4,'EXAM FEES'!$A$5:$A$404,'EXAM FEES'!$C$5:$C$404,""),"")
A7: Student Name | B7: =IFERROR(_xludf.XLOOKUP($B$4,'EXAM FEES'!$A$5:$A$404,'EXAM FEES'!$D$5:$D$404,""),"")
A8: Class | B8: =IFERROR(_xludf.XLOOKUP($B$4,'EXAM FEES'!$A$5:$A$404,'EXAM FEES'!$E$5:$E$404,""),"")
A9: Exam / Term | B9: =IFERROR(_xludf.XLOOKUP($B$4,'EXAM FEES'!$A$5:$A$404,'EXAM FEES'!$F$5:$F$404,""),"")
A10: Amount Paid | B10: =IFERROR(_xludf.XLOOKUP($B$4,'EXAM FEES'!$A$5:$A$404,'EXAM FEES'!$H$5:$H$404,""),"")
A11: Date | B11: =IFERROR(_xludf.XLOOKUP($B$4,'EXAM FEES'!$A$5:$A$404,'EXAM FEES'!$B$5:$B$404,""),"")
A14: Received with thanks for examination fees.
A18: Administrator: ______________________________ | F18: Date: __________________

Sheet DASHBOARD
A1: MNA MANAGEMENT DASHBOARD
A2: Management overview • formulas update when records are entered
A4: Total Students | D4: Active Students | G4: Teachers | J4: Fees Collected
A5: =COUNTIF(STUDENTS!$C$5:$C$204,"<>") -> 42 | D5: =COUNTIF(STUDENTS!$M$5:$M$204,"Active") -> 42 | G5: =COUNTIF(TEACHERS!$B$5:$B$24,"<>") -> 0 | J5: =SUM(FEES!$I$5:$I$1004)+SUM('EXAM FEES'!$H$5:$H$404) -> 0
A8: Outstanding Exam Fees | D8: Attendance % | G8: Results Entered | J8: Average Result
A9: =SUM('EXAM FEES'!$I$5:$I$404) -> 0 | D9: =IFERROR(COUNTIF(ATTENDANCE!$F$5:$F$1204,"Present")/COUNTA(ATTENDANCE!$F$5:$F$1204),0) -> 0 | G9: =COUNT(RESULTS!$L$5:$L$1004) -> 0 | J9: =IFERROR(AVERAGE(RESULTS!$L$5:$L$1004),0) -> 0
A12: ENROLLMENT BY CLASS | E12: GRADE DISTRIBUTION
A13: Grade | B13: Count
A14: =SETTINGS!B18 -> Class 1 | B14: =COUNTIF(STUDENTS!$L$5:$L$204,A14) -> 0 | C14: =COUNTIFS(STUDENTS!$L$5:$L$204,A14,STUDENTS!$M$5:$M$204,"Active") -> 0 | E14: A | F14: =COUNTIF(RESULTS!$M$5:$M$1004,E14) -> 0
A15: =SETTINGS!B19 -> Class 2 | B15: =COUNTIF(STUDENTS!$L$5:$L$204,A15) -> 15 | C15: =COUNTIFS(STUDENTS!$L$5:$L$204,A15,STUDENTS!$M$5:$M$204,"Active") -> 15 | E15: B | F15: =COUNTIF(RESULTS!$M$5:$M$1004,E15) -> 0
A16: =SETTINGS!B20 -> Class 3 | B16: =COUNTIF(STUDENTS!$L$5:$L$204,A16) -> 10 | C16: =COUNTIFS(STUDENTS!$L$5:$L$204,A16,STUDENTS!$M$5:$M$204,"Active") -> 10 | E16: C | F16: =COUNTIF(RESULTS!$M$5:$M$1004,E16) -> 0
A17: =SETTINGS!B21 -> Class 4 | B17: =COUNTIF(STUDENTS!$L$5:$L$204,A17) -> 10 | C17: =COUNTIFS(STUDENTS!$L$5:$L$204,A17,STUDENTS!$M$5:$M$204,"Active") -> 10 | E17: D | F17: =COUNTIF(RESULTS!$M$5:$M$1004,E17) -> 0
A18: =SETTINGS!B22 -> Class 5 | B18: =COUNTIF(STUDENTS!$L$5:$L$204,A18) -> 7 | C18: =COUNTIFS(STUDENTS!$L$5:$L$204,A18,STUDENTS!$M$5:$M$204,"Active") -> 7 | E18: F | F18: =COUNTIF(RESULTS!$M$5:$M$1004,E18) -> 0
A19: =SETTINGS!B23 -> Class 6 | B19: =COUNTIF(STUDENTS!$L$5:$L$204,A19) -> 0 | C19: =COUNTIFS(STUDENTS!$L$5:$L$204,A19,STUDENTS!$M$5:$M$204,"Active") -> 0
